ERROR 2017-02-08 10:18:03,424 views 6411 140350626912000 邮件发送失败: (535, b'5.7.8 authentication failed')ERROR 2017-10-07 10:11:28,866 exception 12102 140324119840512 Internal Server Error: /
Traceback (most recent call last):
  File "/home/ming/.env/blog/lib/python3.5/site-packages/django/db/backends/utils.py", line 64, in execute
    return self.cursor.execute(sql, params)
  File "/home/ming/.env/blog/lib/python3.5/site-packages/django/db/backends/mysql/base.py", line 112, in execute
    return self.cursor.execute(query, args)
  File "/home/ming/.env/blog/lib/python3.5/site-packages/pymysql/cursors.py", line 166, in execute
    result = self._query(query)
  File "/home/ming/.env/blog/lib/python3.5/site-packages/pymysql/cursors.py", line 322, in _query
    conn.query(q)
  File "/home/ming/.env/blog/lib/python3.5/site-packages/pymysql/connections.py", line 856, in query
    self._affected_rows = self._read_query_result(unbuffered=unbuffered)
  File "/home/ming/.env/blog/lib/python3.5/site-packages/pymysql/connections.py", line 1057, in _read_query_result
    result.read()
  File "/home/ming/.env/blog/lib/python3.5/site-packages/pymysql/connections.py", line 1340, in read
    first_packet = self.connection._read_packet()
  File "/home/ming/.env/blog/lib/python3.5/site-packages/pymysql/connections.py", line 1014, in _read_packet
    packet.check_error()
  File "/home/ming/.env/blog/lib/python3.5/site-packages/pymysql/connections.py", line 393, in check_error
    err.raise_mysql_exception(self._data)
  File "/home/ming/.env/blog/lib/python3.5/site-packages/pymysql/err.py", line 107, in raise_mysql_exception
    raise errorclass(errno, errval)
pymysql.err.ProgrammingError: (1146, "Table 'blog.app_article' doesn't exist")

The above exception was the direct cause of the following exception:

Traceback (most recent call last):
  File "/home/ming/.env/blog/lib/python3.5/site-packages/django/core/handlers/exception.py", line 39, in inner
    response = get_response(request)
  File "/home/ming/.env/blog/lib/python3.5/site-packages/django/core/handlers/base.py", line 187, in _get_response
    response = self.process_exception_by_middleware(e, request)
  File "/home/ming/.env/blog/lib/python3.5/site-packages/django/core/handlers/base.py", line 185, in _get_response
    response = wrapped_callback(request, *callback_args, **callback_kwargs)
  File "/home/ming/.env/blog/lib/python3.5/site-packages/django/views/generic/base.py", line 68, in view
    return self.dispatch(request, *args, **kwargs)
  File "/home/ming/.env/blog/lib/python3.5/site-packages/django/views/generic/base.py", line 88, in dispatch
    return handler(request, *args, **kwargs)
  File "/home/ming/.env/blog/lib/python3.5/site-packages/django/views/generic/list.py", line 159, in get
    self.object_list = self.get_queryset()
  File "/home/ming/projects/blog/app/views.py", line 29, in get_queryset
    for article in article_list:
  File "/home/ming/.env/blog/lib/python3.5/site-packages/django/db/models/query.py", line 256, in __iter__
    self._fetch_all()
  File "/home/ming/.env/blog/lib/python3.5/site-packages/django/db/models/query.py", line 1087, in _fetch_all
    self._result_cache = list(self.iterator())
  File "/home/ming/.env/blog/lib/python3.5/site-packages/django/db/models/query.py", line 54, in __iter__
    results = compiler.execute_sql()
  File "/home/ming/.env/blog/lib/python3.5/site-packages/django/db/models/sql/compiler.py", line 835, in execute_sql
    cursor.execute(sql, params)
  File "/home/ming/.env/blog/lib/python3.5/site-packages/django/db/backends/utils.py", line 79, in execute
    return super(CursorDebugWrapper, self).execute(sql, params)
  File "/home/ming/.env/blog/lib/python3.5/site-packages/django/db/backends/utils.py", line 64, in execute
    return self.cursor.execute(sql, params)
  File "/home/ming/.env/blog/lib/python3.5/site-packages/django/db/utils.py", line 94, in __exit__
    six.reraise(dj_exc_type, dj_exc_value, traceback)
  File "/home/ming/.env/blog/lib/python3.5/site-packages/django/utils/six.py", line 685, in reraise
    raise value.with_traceback(tb)
  File "/home/ming/.env/blog/lib/python3.5/site-packages/django/db/backends/utils.py", line 64, in execute
    return self.cursor.execute(sql, params)
  File "/home/ming/.env/blog/lib/python3.5/site-packages/django/db/backends/mysql/base.py", line 112, in execute
    return self.cursor.execute(query, args)
  File "/home/ming/.env/blog/lib/python3.5/site-packages/pymysql/cursors.py", line 166, in execute
    result = self._query(query)
  File "/home/ming/.env/blog/lib/python3.5/site-packages/pymysql/cursors.py", line 322, in _query
    conn.query(q)
  File "/home/ming/.env/blog/lib/python3.5/site-packages/pymysql/connections.py", line 856, in query
    self._affected_rows = self._read_query_result(unbuffered=unbuffered)
  File "/home/ming/.env/blog/lib/python3.5/site-packages/pymysql/connections.py", line 1057, in _read_query_result
    result.read()
  File "/home/ming/.env/blog/lib/python3.5/site-packages/pymysql/connections.py", line 1340, in read
    first_packet = self.connection._read_packet()
  File "/home/ming/.env/blog/lib/python3.5/site-packages/pymysql/connections.py", line 1014, in _read_packet
    packet.check_error()
  File "/home/ming/.env/blog/lib/python3.5/site-packages/pymysql/connections.py", line 393, in check_error
    err.raise_mysql_exception(self._data)
  File "/home/ming/.env/blog/lib/python3.5/site-packages/pymysql/err.py", line 107, in raise_mysql_exception
    raise errorclass(errno, errval)
django.db.utils.ProgrammingError: (1146, "Table 'blog.app_article' doesn't exist")
ERROR 2017-10-07 10:24:31,582 views 13373 140030823622400 邮件发送失败: Error 111 connecting to localhost:6379. Connection refused.
ERROR 2017-10-07 11:02:40,385 views 26434 139984518506240 邮件发送失败: (535, b'5.7.8 authentication failed')
ERROR 2017-10-07 11:03:13,011 views 26595 140543109977856 邮件发送失败: (535, b'5.7.12 SMTP access disabled')
ERROR 2018-05-19 10:14:33,083 views 21541 139676467410688 邮件发送失败: celery_send_email() takes 4 positional arguments but 5 were given
ERROR 2018-05-19 10:19:53,122 views 21685 139803501729536 邮件发送失败: celery_send_email() takes 4 positional arguments but 5 were given
ERROR 2018-05-19 10:23:12,929 views 21770 140602129774336 邮件发送失败: celery_send_email() takes 4 positional arguments but 5 were given
ERROR 2018-05-19 10:33:04,213 tasks 21934 140517099198208 邮件发送失败: [Errno -2] Name or service not known
